<?xml version="1.0" encoding="utf-8"?>
<!-- This URDF was automatically created by SolidWorks to URDF Exporter! Originally created by Stephen Brawner (brawner@gmail.com) 
     Commit Version: 1.6.0-4-g7f85cfe  Build Version: 1.6.7995.38578
     For more information, please see http://wiki.ros.org/sw_urdf_exporter -->
<robot
  name="RobotAssembly">
  <link
    name="base_Frame">
    <inertial>
      <origin
        xyz="-0.00392828513304835 -5.27957094589629E-18 0.0197084096565698"
        rpy="0 0 0" />
      <mass
        value="0.398803913878024" />
      <inertia
        ixx="0.000383634062492965"
        ixy="-5.59526705517806E-20"
        ixz="5.15665640521899E-06"
        iyy="0.000377479950170546"
        iyz="-3.26597973458209E-20"
        izz="0.000652663421267234" />
    </inertial>
    <visual>
      <origin
        xyz="0 0 0"
        rpy="0 0 0" />
      <geometry>
        <mesh
          filename="package://RobotAssembly/meshes/base_Frame.STL" />
      </geometry>
      <material
        name="">
        <color
          rgba="0.792156862745098 0.819607843137255 0.933333333333333 1" />
      </material>
    </visual>
    <collision>
      <origin
        xyz="0 0 0"
        rpy="0 0 0" />
      <geometry>
        <mesh
          filename="package://RobotAssembly/meshes/base_Frame.STL" />
      </geometry>
    </collision>
  </link>
  <link
    name="BaseLink">
    <inertial>
      <origin
        xyz="-0.00392828513304835 -5.27957094589629E-18 0.0197084096565698"
        rpy="0 0 0" />
      <mass
        value="0.398803913878024" />
      <inertia
        ixx="0.000383634062492965"
        ixy="-5.54350994038197E-20"
        ixz="5.15665640521899E-06"
        iyy="0.000377479950170546"
        iyz="-3.26192607764251E-20"
        izz="0.000652663421267234" />
    </inertial>
    <visual>
      <origin
        xyz="0 0 0"
        rpy="0 0 0" />
      <geometry>
        <mesh
          filename="package://RobotAssembly/meshes/BaseLink.STL" />
      </geometry>
      <material
        name="">
        <color
          rgba="0.792156862745098 0.819607843137255 0.933333333333333 1" />
      </material>
    </visual>
    <collision>
      <origin
        xyz="0 0 0"
        rpy="0 0 0" />
      <geometry>
        <mesh
          filename="package://RobotAssembly/meshes/BaseLink.STL" />
      </geometry>
    </collision>
  </link>
  <joint
    name="BaseLinkJoint"
    type="fixed">
    <origin
      xyz="0 0 0"
      rpy="0 0 0" />
    <parent
      link="base_Frame" />
    <child
      link="BaseLink" />
    <axis
      xyz="0 0 0" />
  </joint>
  <link
    name="J1_Link">
    <inertial>
      <origin
        xyz="5.19780395945533E-17 -0.00220626005450383 0.0200689923926743"
        rpy="0 0 0" />
      <mass
        value="0.178308396338367" />
      <inertia
        ixx="0.000290696734206688"
        ixy="-5.58317885264175E-11"
        ixz="4.54620357960477E-20"
        iyy="0.000146889533548349"
        iyz="-3.34224178976832E-07"
        izz="0.000331186535139949" />
    </inertial>
    <visual>
      <origin
        xyz="0 0 0"
        rpy="0 0 0" />
      <geometry>
        <mesh
          filename="package://RobotAssembly/meshes/J1_Link.STL" />
      </geometry>
      <material
        name="">
        <color
          rgba="0.792156862745098 0.819607843137255 0.933333333333333 1" />
      </material>
    </visual>
    <collision>
      <origin
        xyz="0 0 0"
        rpy="0 0 0" />
      <geometry>
        <mesh
          filename="package://RobotAssembly/meshes/J1_Link.STL" />
      </geometry>
    </collision>
  </link>
  <joint
    name="J1"
    type="revolute">
    <origin
      xyz="0 0 0.04"
      rpy="0 0 0" />
    <parent
      link="BaseLink" />
    <child
      link="J1_Link" />
    <axis
      xyz="0 0 -1" />
    <limit
      lower="-6.2856"
      upper="6.2856"
      effort="0"
      velocity="0" />
  </joint>
  <link
    name="J2_Link">
    <inertial>
      <origin
        xyz="0.0341625857117514 4.81563057101389E-08 -0.00348814488795987"
        rpy="0 0 0" />
      <mass
        value="0.20493853476852" />
      <inertia
        ixx="5.25009121788374E-05"
        ixy="-2.51992987676672E-11"
        ixz="1.05086162925748E-08"
        iyy="0.000293309909415094"
        iyz="3.0817287744597E-10"
        izz="0.000339163519667511" />
    </inertial>
    <visual>
      <origin
        xyz="0 0 0"
        rpy="0 0 0" />
      <geometry>
        <mesh
          filename="package://RobotAssembly/meshes/J2_Link.STL" />
      </geometry>
      <material
        name="">
        <color
          rgba="0.792156862745098 0.819607843137255 0.933333333333333 1" />
      </material>
    </visual>
    <collision>
      <origin
        xyz="0 0 0"
        rpy="0 0 0" />
      <geometry>
        <mesh
          filename="package://RobotAssembly/meshes/J2_Link.STL" />
      </geometry>
    </collision>
  </link>
  <joint
    name="J2"
    type="revolute">
    <origin
      xyz="0 0 0.0450235133971798"
      rpy="1.5707963267949 -1.57001254680866 -3.14159265358979" />
    <parent
      link="J1_Link" />
    <child
      link="J2_Link" />
    <axis
      xyz="0 0 1" />
    <limit
      lower="-6.2856"
      upper="6.2856"
      effort="0"
      velocity="0" />
  </joint>
  <link
    name="J3_Link">
    <inertial>
      <origin
        xyz="0.0085983743704942 -0.0192799171048054 -0.0351458907841485"
        rpy="0 0 0" />
      <mass
        value="0.211104401938319" />
      <inertia
        ixx="0.00010201352545001"
        ixy="9.23339515566093E-06"
        ixz="1.28811604797203E-06"
        iyy="7.66727826172985E-05"
        iyz="-9.60803527585616E-07"
        izz="8.84124778948434E-05" />
    </inertial>
    <visual>
      <origin
        xyz="0 0 0"
        rpy="0 0 0" />
      <geometry>
        <mesh
          filename="package://RobotAssembly/meshes/J3_Link.STL" />
      </geometry>
      <material
        name="">
        <color
          rgba="0.792156862745098 0.819607843137255 0.933333333333333 1" />
      </material>
    </visual>
    <collision>
      <origin
        xyz="0 0 0"
        rpy="0 0 0" />
      <geometry>
        <mesh
          filename="package://RobotAssembly/meshes/J3_Link.STL" />
      </geometry>
    </collision>
  </link>
  <joint
    name="J3"
    type="revolute">
    <origin
      xyz="0.0999764866100428 0 0.035"
      rpy="0 0 1.57158010678112" />
    <parent
      link="J2_Link" />
    <child
      link="J3_Link" />
    <axis
      xyz="0 0 1" />
    <limit
      lower="-6.2856"
      upper="6.2856"
      effort="0"
      velocity="0" />
  </joint>
  <link
    name="J4_Link">
    <inertial>
      <origin
        xyz="8.35079161376484E-07 -0.00676193137349457 0.0181683173855942"
        rpy="0 0 0" />
      <mass
        value="0.0521282135415929" />
      <inertia
        ixx="3.7593062578374E-05"
        ixy="1.5052840427318E-09"
        ixz="-1.19434860111226E-09"
        iyy="1.15235892953846E-05"
        iyz="-7.13691998393439E-08"
        izz="3.0795899659119E-05" />
    </inertial>
    <visual>
      <origin
        xyz="0 0 0"
        rpy="0 0 0" />
      <geometry>
        <mesh
          filename="package://RobotAssembly/meshes/J4_Link.STL" />
      </geometry>
      <material
        name="">
        <color
          rgba="0.792156862745098 0.819607843137255 0.933333333333333 1" />
      </material>
    </visual>
    <collision>
      <origin
        xyz="0 0 0"
        rpy="0 0 0" />
      <geometry>
        <mesh
          filename="package://RobotAssembly/meshes/J4_Link.STL" />
      </geometry>
    </collision>
  </link>
  <joint
    name="J4"
    type="revolute">
    <origin
      xyz="0.0399655013979157 -0.0440313376813969 -0.0344999999999999"
      rpy="1.5707963267949 0 1.57001254680867" />
    <parent
      link="J3_Link" />
    <child
      link="J4_Link" />
    <axis
      xyz="0 0 -1" />
    <limit
      lower="-6.2856"
      upper="6.2856"
      effort="0"
      velocity="0" />
  </joint>
  <link
    name="J5_Link">
    <inertial>
      <origin
        xyz="3.94129173741931E-15 -0.0258816481211883 -0.0341794222651043"
        rpy="0 0 0" />
      <mass
        value="0.189700976705942" />
      <inertia
        ixx="0.000100351816110413"
        ixy="-2.82973578130243E-10"
        ixz="2.82973578769169E-10"
        iyy="7.16468415501826E-05"
        iyz="-2.54245342930596E-06"
        izz="8.16276490016628E-05" />
    </inertial>
    <visual>
      <origin
        xyz="0 0 0"
        rpy="0 0 0" />
      <geometry>
        <mesh
          filename="package://RobotAssembly/meshes/J5_Link.STL" />
      </geometry>
      <material
        name="">
        <color
          rgba="0.752941176470588 0.752941176470588 0.752941176470588 1" />
      </material>
    </visual>
    <collision>
      <origin
        xyz="0 0 0"
        rpy="0 0 0" />
      <geometry>
        <mesh
          filename="package://RobotAssembly/meshes/J5_Link.STL" />
      </geometry>
    </collision>
  </link>
  <joint
    name="J5"
    type="revolute">
    <origin
      xyz="0 0.0345 0.0419999999999999"
      rpy="-1.5707963267949 0 0" />
    <parent
      link="J4_Link" />
    <child
      link="J5_Link" />
    <axis
      xyz="0 0 1" />
    <limit
      lower="-6.2856"
      upper="6.2856"
      effort="0"
      velocity="0" />
  </joint>
  <link
    name="J6_Link">
    <inertial>
      <origin
        xyz="2.10273537232242E-06 -4.65350489550461E-06 -0.0298923940103484"
        rpy="0 0 0" />
      <mass
        value="0.00114582999188719" />
      <inertia
        ixx="3.32285500557153E-07"
        ixy="-2.54807966119436E-11"
        ixz="3.07683493859108E-10"
        iyy="3.32330377628855E-07"
        iyz="-6.80925742643999E-10"
        izz="3.54273266881593E-09" />
    </inertial>
    <visual>
      <origin
        xyz="0 0 0"
        rpy="0 0 0" />
      <geometry>
        <mesh
          filename="package://RobotAssembly/meshes/J6_Link.STL" />
      </geometry>
      <material
        name="">
        <color
          rgba="0.737254901960784 0.776470588235294 0.8 1" />
      </material>
    </visual>
    <collision>
      <origin
        xyz="0 0 0"
        rpy="0 0 0" />
      <geometry>
        <mesh
          filename="package://RobotAssembly/meshes/J6_Link.STL" />
      </geometry>
    </collision>
  </link>
  <joint
    name="J6"
    type="revolute">
    <origin
      xyz="-1.4128E-05 -0.087 -0.032969"
      rpy="1.5708 0 0" />
    <parent
      link="J5_Link" />
    <child
      link="J6_Link" />
    <axis
      xyz="0 0 -1" />
    <limit
      lower="-6.2856"
      upper="6.2856"
      effort="0"
      velocity="0" />
  </joint>
</robot>